[2021-11-27 17:26:44,963] {taskinstance.py:1035} INFO - Dependencies all met for <TaskInstance: daily-scraping.scraping manual__2021-11-27T09:39:45.785179+00:00 [queued]>
[2021-11-27 17:26:44,969] {taskinstance.py:1035} INFO - Dependencies all met for <TaskInstance: daily-scraping.scraping manual__2021-11-27T09:39:45.785179+00:00 [queued]>
[2021-11-27 17:26:44,969] {taskinstance.py:1241} INFO - 
--------------------------------------------------------------------------------
[2021-11-27 17:26:44,969] {taskinstance.py:1242} INFO - Starting attempt 2 of 2
[2021-11-27 17:26:44,969] {taskinstance.py:1243} INFO - 
--------------------------------------------------------------------------------
[2021-11-27 17:26:44,976] {taskinstance.py:1262} INFO - Executing <Task(BashOperator): scraping> on 2021-11-27 09:39:45.785179+00:00
[2021-11-27 17:26:44,978] {standard_task_runner.py:52} INFO - Started process 21208 to run task
[2021-11-27 17:26:44,983] {standard_task_runner.py:76} INFO - Running: ['airflow', 'tasks', 'run', 'daily-scraping', 'scraping', 'manual__2021-11-27T09:39:45.785179+00:00', '--job-id', '1154', '--raw', '--subdir', 'DAGS_FOLDER/scraping.py', '--cfg-path', '/var/folders/hj/g8v71bv11_gb814qbbwch8zc0000gn/T/tmph86dz4ss', '--error-file', '/var/folders/hj/g8v71bv11_gb814qbbwch8zc0000gn/T/tmphj94mgpu']
[2021-11-27 17:26:44,984] {standard_task_runner.py:77} INFO - Job 1154: Subtask scraping
[2021-11-27 17:26:45,013] {logging_mixin.py:109} INFO - Running <TaskInstance: daily-scraping.scraping manual__2021-11-27T09:39:45.785179+00:00 [running]> on host MacBookPro.local
[2021-11-27 17:26:45,037] {taskinstance.py:1427} INFO - Exporting the following env vars:
AIRFLOW_CTX_DAG_EMAIL=airflow@example.com
AIRFLOW_CTX_DAG_OWNER=airflow
AIRFLOW_CTX_DAG_ID=daily-scraping
AIRFLOW_CTX_TASK_ID=scraping
AIRFLOW_CTX_EXECUTION_DATE=2021-11-27T09:39:45.785179+00:00
AIRFLOW_CTX_DAG_RUN_ID=manual__2021-11-27T09:39:45.785179+00:00
[2021-11-27 17:26:45,037] {subprocess.py:62} INFO - Tmp dir root location: 
 /var/folders/hj/g8v71bv11_gb814qbbwch8zc0000gn/T
[2021-11-27 17:26:45,038] {subprocess.py:74} INFO - Running command: ['bash', '-c', '/Users/Home/Airflow/tasks/scraping.py /Users/Home/Airflow/down']
[2021-11-27 17:26:45,044] {subprocess.py:85} INFO - Output:
[2021-11-27 17:33:53,752] {local_task_job.py:191} WARNING - The recorded hostname MacBookPro.local does not match this instance's hostname 1.0.0.0.0.0.0.0.0.0.0.0.0.0.0.0.0.0.0.0.0.0.0.0.0.0.0.0.0.0.0.0.ip6.arpa
[2021-11-27 17:33:53,766] {process_utils.py:100} INFO - Sending Signals.SIGTERM to GPID 21208
[2021-11-27 17:33:53,768] {taskinstance.py:1411} ERROR - Received SIGTERM. Terminating subprocesses.
[2021-11-27 17:33:53,770] {subprocess.py:99} INFO - Sending SIGTERM signal to process group
[2021-11-27 17:33:53,793] {taskinstance.py:1703} ERROR - Task failed with exception
Traceback (most recent call last):
  File "/usr/local/lib/python3.9/site-packages/airflow/models/taskinstance.py", line 1332, in _run_raw_task
    self._execute_task_with_callbacks(context)
  File "/usr/local/lib/python3.9/site-packages/airflow/models/taskinstance.py", line 1458, in _execute_task_with_callbacks
    result = self._execute_task(context, self.task)
  File "/usr/local/lib/python3.9/site-packages/airflow/models/taskinstance.py", line 1514, in _execute_task
    result = execute_callable(context=context)
  File "/usr/local/lib/python3.9/site-packages/airflow/operators/bash.py", line 178, in execute
    result = self.subprocess_hook.run_command(
  File "/usr/local/lib/python3.9/site-packages/airflow/hooks/subprocess.py", line 87, in run_command
    for raw_line in iter(self.sub_process.stdout.readline, b''):
  File "/usr/local/lib/python3.9/site-packages/airflow/models/taskinstance.py", line 1413, in signal_handler
    raise AirflowException("Task received SIGTERM signal")
airflow.exceptions.AirflowException: Task received SIGTERM signal
[2021-11-27 17:33:53,801] {taskinstance.py:1270} INFO - Marking task as FAILED. dag_id=daily-scraping, task_id=scraping, execution_date=20211127T093945, start_date=20211127T102644, end_date=20211127T103353
[2021-11-27 17:33:53,816] {standard_task_runner.py:88} ERROR - Failed to execute job 1154 for task scraping
Traceback (most recent call last):
  File "/usr/local/lib/python3.9/site-packages/airflow/task/task_runner/standard_task_runner.py", line 85, in _start_by_fork
    args.func(args, dag=self.dag)
  File "/usr/local/lib/python3.9/site-packages/airflow/cli/cli_parser.py", line 48, in command
    return func(*args, **kwargs)
  File "/usr/local/lib/python3.9/site-packages/airflow/utils/cli.py", line 92, in wrapper
    return f(*args, **kwargs)
  File "/usr/local/lib/python3.9/site-packages/airflow/cli/commands/task_command.py", line 292, in task_run
    _run_task_by_selected_method(args, dag, ti)
  File "/usr/local/lib/python3.9/site-packages/airflow/cli/commands/task_command.py", line 107, in _run_task_by_selected_method
    _run_raw_task(args, ti)
  File "/usr/local/lib/python3.9/site-packages/airflow/cli/commands/task_command.py", line 180, in _run_raw_task
    ti._run_raw_task(
  File "/usr/local/lib/python3.9/site-packages/airflow/utils/session.py", line 70, in wrapper
    return func(*args, session=session, **kwargs)
  File "/usr/local/lib/python3.9/site-packages/airflow/models/taskinstance.py", line 1332, in _run_raw_task
    self._execute_task_with_callbacks(context)
  File "/usr/local/lib/python3.9/site-packages/airflow/models/taskinstance.py", line 1458, in _execute_task_with_callbacks
    result = self._execute_task(context, self.task)
  File "/usr/local/lib/python3.9/site-packages/airflow/models/taskinstance.py", line 1514, in _execute_task
    result = execute_callable(context=context)
  File "/usr/local/lib/python3.9/site-packages/airflow/operators/bash.py", line 178, in execute
    result = self.subprocess_hook.run_command(
  File "/usr/local/lib/python3.9/site-packages/airflow/hooks/subprocess.py", line 87, in run_command
    for raw_line in iter(self.sub_process.stdout.readline, b''):
  File "/usr/local/lib/python3.9/site-packages/airflow/models/taskinstance.py", line 1413, in signal_handler
    raise AirflowException("Task received SIGTERM signal")
airflow.exceptions.AirflowException: Task received SIGTERM signal
[2021-11-27 17:33:53,868] {process_utils.py:66} INFO - Process psutil.Process(pid=21209, status='terminated', started='17:26:45') (21209) terminated with exit code None
[2021-11-27 17:33:53,869] {process_utils.py:66} INFO - Process psutil.Process(pid=21208, status='terminated', exitcode=1, started='17:26:44') (21208) terminated with exit code 1
