[2021-11-27 05:15:37,931] {taskinstance.py:1035} INFO - Dependencies all met for <TaskInstance: daily-scraping.scraping manual__2021-11-26T22:15:34.949067+00:00 [queued]>
[2021-11-27 05:15:37,936] {taskinstance.py:1035} INFO - Dependencies all met for <TaskInstance: daily-scraping.scraping manual__2021-11-26T22:15:34.949067+00:00 [queued]>
[2021-11-27 05:15:37,937] {taskinstance.py:1241} INFO - 
--------------------------------------------------------------------------------
[2021-11-27 05:15:37,937] {taskinstance.py:1242} INFO - Starting attempt 1 of 2
[2021-11-27 05:15:37,937] {taskinstance.py:1243} INFO - 
--------------------------------------------------------------------------------
[2021-11-27 05:15:37,944] {taskinstance.py:1262} INFO - Executing <Task(BashOperator): scraping> on 2021-11-26 22:15:34.949067+00:00
[2021-11-27 05:15:37,946] {standard_task_runner.py:52} INFO - Started process 20496 to run task
[2021-11-27 05:15:37,951] {standard_task_runner.py:76} INFO - Running: ['airflow', 'tasks', 'run', 'daily-scraping', 'scraping', 'manual__2021-11-26T22:15:34.949067+00:00', '--job-id', '25', '--raw', '--subdir', 'DAGS_FOLDER/scraping.py', '--cfg-path', '/var/folders/hj/g8v71bv11_gb814qbbwch8zc0000gn/T/tmpahoto1pv', '--error-file', '/var/folders/hj/g8v71bv11_gb814qbbwch8zc0000gn/T/tmps1m6mroy']
[2021-11-27 05:15:37,953] {standard_task_runner.py:77} INFO - Job 25: Subtask scraping
[2021-11-27 05:15:37,982] {logging_mixin.py:109} INFO - Running <TaskInstance: daily-scraping.scraping manual__2021-11-26T22:15:34.949067+00:00 [running]> on host 1.0.0.0.0.0.0.0.0.0.0.0.0.0.0.0.0.0.0.0.0.0.0.0.0.0.0.0.0.0.0.0.ip6.arpa
[2021-11-27 05:15:38,009] {taskinstance.py:1427} INFO - Exporting the following env vars:
AIRFLOW_CTX_DAG_EMAIL=airflow@example.com
AIRFLOW_CTX_DAG_OWNER=airflow
AIRFLOW_CTX_DAG_ID=daily-scraping
AIRFLOW_CTX_TASK_ID=scraping
AIRFLOW_CTX_EXECUTION_DATE=2021-11-26T22:15:34.949067+00:00
AIRFLOW_CTX_DAG_RUN_ID=manual__2021-11-26T22:15:34.949067+00:00
[2021-11-27 05:15:38,009] {subprocess.py:62} INFO - Tmp dir root location: 
 /var/folders/hj/g8v71bv11_gb814qbbwch8zc0000gn/T
[2021-11-27 05:15:38,010] {subprocess.py:74} INFO - Running command: ['bash', '-c', '/Users/Home/Airflow/tasks/scraping.py /Users/Home/Airflow/down']
[2021-11-27 05:15:38,015] {subprocess.py:85} INFO - Output:
[2021-11-27 05:21:51,145] {local_task_job.py:191} WARNING - The recorded hostname 1.0.0.0.0.0.0.0.0.0.0.0.0.0.0.0.0.0.0.0.0.0.0.0.0.0.0.0.0.0.0.0.ip6.arpa does not match this instance's hostname MacBookPro.local
[2021-11-27 05:21:51,184] {process_utils.py:100} INFO - Sending Signals.SIGTERM to GPID 20496
[2021-11-27 05:21:51,194] {taskinstance.py:1411} ERROR - Received SIGTERM. Terminating subprocesses.
[2021-11-27 05:21:51,213] {subprocess.py:99} INFO - Sending SIGTERM signal to process group
[2021-11-27 05:21:51,243] {taskinstance.py:1703} ERROR - Task failed with exception
Traceback (most recent call last):
  File "/usr/local/lib/python3.9/site-packages/airflow/models/taskinstance.py", line 1332, in _run_raw_task
    self._execute_task_with_callbacks(context)
  File "/usr/local/lib/python3.9/site-packages/airflow/models/taskinstance.py", line 1458, in _execute_task_with_callbacks
    result = self._execute_task(context, self.task)
  File "/usr/local/lib/python3.9/site-packages/airflow/models/taskinstance.py", line 1514, in _execute_task
    result = execute_callable(context=context)
  File "/usr/local/lib/python3.9/site-packages/airflow/operators/bash.py", line 178, in execute
    result = self.subprocess_hook.run_command(
  File "/usr/local/lib/python3.9/site-packages/airflow/hooks/subprocess.py", line 87, in run_command
    for raw_line in iter(self.sub_process.stdout.readline, b''):
  File "/usr/local/lib/python3.9/site-packages/airflow/models/taskinstance.py", line 1413, in signal_handler
    raise AirflowException("Task received SIGTERM signal")
airflow.exceptions.AirflowException: Task received SIGTERM signal
[2021-11-27 05:21:51,250] {taskinstance.py:1270} INFO - Marking task as UP_FOR_RETRY. dag_id=daily-scraping, task_id=scraping, execution_date=20211126T221534, start_date=20211126T221537, end_date=20211126T222151
[2021-11-27 05:21:51,265] {standard_task_runner.py:88} ERROR - Failed to execute job 25 for task scraping
Traceback (most recent call last):
  File "/usr/local/lib/python3.9/site-packages/airflow/task/task_runner/standard_task_runner.py", line 85, in _start_by_fork
    args.func(args, dag=self.dag)
  File "/usr/local/lib/python3.9/site-packages/airflow/cli/cli_parser.py", line 48, in command
    return func(*args, **kwargs)
  File "/usr/local/lib/python3.9/site-packages/airflow/utils/cli.py", line 92, in wrapper
    return f(*args, **kwargs)
  File "/usr/local/lib/python3.9/site-packages/airflow/cli/commands/task_command.py", line 292, in task_run
    _run_task_by_selected_method(args, dag, ti)
  File "/usr/local/lib/python3.9/site-packages/airflow/cli/commands/task_command.py", line 107, in _run_task_by_selected_method
    _run_raw_task(args, ti)
  File "/usr/local/lib/python3.9/site-packages/airflow/cli/commands/task_command.py", line 180, in _run_raw_task
    ti._run_raw_task(
  File "/usr/local/lib/python3.9/site-packages/airflow/utils/session.py", line 70, in wrapper
    return func(*args, session=session, **kwargs)
  File "/usr/local/lib/python3.9/site-packages/airflow/models/taskinstance.py", line 1332, in _run_raw_task
    self._execute_task_with_callbacks(context)
  File "/usr/local/lib/python3.9/site-packages/airflow/models/taskinstance.py", line 1458, in _execute_task_with_callbacks
    result = self._execute_task(context, self.task)
  File "/usr/local/lib/python3.9/site-packages/airflow/models/taskinstance.py", line 1514, in _execute_task
    result = execute_callable(context=context)
  File "/usr/local/lib/python3.9/site-packages/airflow/operators/bash.py", line 178, in execute
    result = self.subprocess_hook.run_command(
  File "/usr/local/lib/python3.9/site-packages/airflow/hooks/subprocess.py", line 87, in run_command
    for raw_line in iter(self.sub_process.stdout.readline, b''):
  File "/usr/local/lib/python3.9/site-packages/airflow/models/taskinstance.py", line 1413, in signal_handler
    raise AirflowException("Task received SIGTERM signal")
airflow.exceptions.AirflowException: Task received SIGTERM signal
[2021-11-27 05:21:51,286] {process_utils.py:66} INFO - Process psutil.Process(pid=20497, status='terminated', started='05:15:38') (20497) terminated with exit code None
[2021-11-27 05:21:51,298] {process_utils.py:66} INFO - Process psutil.Process(pid=20496, status='terminated', exitcode=1, started='05:15:37') (20496) terminated with exit code 1
