[2021-11-27 11:51:07,076] {taskinstance.py:1035} INFO - Dependencies all met for <TaskInstance: elt.cleaning scheduled__2021-11-27T04:50:00+00:00 [queued]>
[2021-11-27 11:51:07,077] {taskinstance.py:1035} INFO - Dependencies all met for <TaskInstance: elt.cleaning scheduled__2021-11-27T04:50:00+00:00 [queued]>
[2021-11-27 11:51:07,081] {taskinstance.py:1035} INFO - Dependencies all met for <TaskInstance: elt.cleaning scheduled__2021-11-27T04:50:00+00:00 [queued]>
[2021-11-27 11:51:07,081] {taskinstance.py:1241} INFO - 
--------------------------------------------------------------------------------
[2021-11-27 11:51:07,081] {taskinstance.py:1242} INFO - Starting attempt 1 of 2
[2021-11-27 11:51:07,081] {taskinstance.py:1243} INFO - 
--------------------------------------------------------------------------------
[2021-11-27 11:51:07,082] {taskinstance.py:1035} INFO - Dependencies all met for <TaskInstance: elt.cleaning scheduled__2021-11-27T04:50:00+00:00 [queued]>
[2021-11-27 11:51:07,082] {taskinstance.py:1241} INFO - 
--------------------------------------------------------------------------------
[2021-11-27 11:51:07,083] {taskinstance.py:1242} INFO - Starting attempt 1 of 2
[2021-11-27 11:51:07,083] {taskinstance.py:1243} INFO - 
--------------------------------------------------------------------------------
[2021-11-27 11:51:07,088] {taskinstance.py:1262} INFO - Executing <Task(BashOperator): cleaning> on 2021-11-27 04:50:00+00:00
[2021-11-27 11:51:07,091] {standard_task_runner.py:52} INFO - Started process 12435 to run task
[2021-11-27 11:51:07,094] {taskinstance.py:1262} INFO - Executing <Task(BashOperator): cleaning> on 2021-11-27 04:50:00+00:00
[2021-11-27 11:51:07,096] {standard_task_runner.py:52} INFO - Started process 12436 to run task
[2021-11-27 11:51:07,097] {standard_task_runner.py:76} INFO - Running: ['airflow', 'tasks', 'run', 'elt', 'cleaning', 'scheduled__2021-11-27T04:50:00+00:00', '--job-id', '601', '--raw', '--subdir', 'DAGS_FOLDER/processing.py', '--cfg-path', '/var/folders/hj/g8v71bv11_gb814qbbwch8zc0000gn/T/tmpjeb3pg8z', '--error-file', '/var/folders/hj/g8v71bv11_gb814qbbwch8zc0000gn/T/tmpyndhkkfp']
[2021-11-27 11:51:07,098] {standard_task_runner.py:77} INFO - Job 601: Subtask cleaning
[2021-11-27 11:51:07,101] {standard_task_runner.py:76} INFO - Running: ['airflow', 'tasks', 'run', 'elt', 'cleaning', 'scheduled__2021-11-27T04:50:00+00:00', '--job-id', '602', '--raw', '--subdir', 'DAGS_FOLDER/processing.py', '--cfg-path', '/var/folders/hj/g8v71bv11_gb814qbbwch8zc0000gn/T/tmpywxol3v6', '--error-file', '/var/folders/hj/g8v71bv11_gb814qbbwch8zc0000gn/T/tmps2w6auto']
[2021-11-27 11:51:07,103] {standard_task_runner.py:77} INFO - Job 602: Subtask cleaning
[2021-11-27 11:51:07,128] {logging_mixin.py:109} INFO - Running <TaskInstance: elt.cleaning scheduled__2021-11-27T04:50:00+00:00 [running]> on host 1.0.0.0.0.0.0.0.0.0.0.0.0.0.0.0.0.0.0.0.0.0.0.0.0.0.0.0.0.0.0.0.ip6.arpa
[2021-11-27 11:51:07,132] {logging_mixin.py:109} INFO - Running <TaskInstance: elt.cleaning scheduled__2021-11-27T04:50:00+00:00 [running]> on host 1.0.0.0.0.0.0.0.0.0.0.0.0.0.0.0.0.0.0.0.0.0.0.0.0.0.0.0.0.0.0.0.ip6.arpa
[2021-11-27 11:51:07,160] {taskinstance.py:1427} INFO - Exporting the following env vars:
AIRFLOW_CTX_DAG_EMAIL=airflow@example.com
AIRFLOW_CTX_DAG_OWNER=airflow
AIRFLOW_CTX_DAG_ID=elt
AIRFLOW_CTX_TASK_ID=cleaning
AIRFLOW_CTX_EXECUTION_DATE=2021-11-27T04:50:00+00:00
AIRFLOW_CTX_DAG_RUN_ID=scheduled__2021-11-27T04:50:00+00:00
[2021-11-27 11:51:07,161] {subprocess.py:62} INFO - Tmp dir root location: 
 /var/folders/hj/g8v71bv11_gb814qbbwch8zc0000gn/T
[2021-11-27 11:51:07,162] {subprocess.py:74} INFO - Running command: ['bash', '-c', '/Users/Home/Airflow/tasks/cleaning.py /Users/Home/Airflow/unzip /Users/Home/Airflow/output']
[2021-11-27 11:51:07,168] {subprocess.py:85} INFO - Output:
[2021-11-27 11:51:07,158] {taskinstance.py:1703} ERROR - Task failed with exception
Traceback (most recent call last):
  File "/usr/local/lib/python3.9/site-packages/sqlalchemy/engine/base.py", line 1276, in _execute_context
    self.dialect.do_execute(
  File "/usr/local/lib/python3.9/site-packages/sqlalchemy/engine/default.py", line 608, in do_execute
    cursor.execute(statement, parameters)
sqlite3.IntegrityError: UNIQUE constraint failed: rendered_task_instance_fields.dag_id, rendered_task_instance_fields.task_id, rendered_task_instance_fields.execution_date

The above exception was the direct cause of the following exception:

Traceback (most recent call last):
  File "/usr/local/lib/python3.9/site-packages/airflow/models/taskinstance.py", line 1332, in _run_raw_task
    self._execute_task_with_callbacks(context)
  File "/usr/local/lib/python3.9/site-packages/airflow/models/taskinstance.py", line 1422, in _execute_task_with_callbacks
    RenderedTaskInstanceFields.write(RenderedTaskInstanceFields(ti=self, render_templates=False))
  File "/usr/local/lib/python3.9/site-packages/airflow/utils/session.py", line 70, in wrapper
    return func(*args, session=session, **kwargs)
  File "/usr/local/Cellar/python@3.9/3.9.9/Frameworks/Python.framework/Versions/3.9/lib/python3.9/contextlib.py", line 126, in __exit__
    next(self.gen)
  File "/usr/local/lib/python3.9/site-packages/airflow/utils/session.py", line 32, in create_session
    session.commit()
  File "/usr/local/lib/python3.9/site-packages/sqlalchemy/orm/session.py", line 1046, in commit
    self.transaction.commit()
  File "/usr/local/lib/python3.9/site-packages/sqlalchemy/orm/session.py", line 504, in commit
    self._prepare_impl()
  File "/usr/local/lib/python3.9/site-packages/sqlalchemy/orm/session.py", line 483, in _prepare_impl
    self.session.flush()
  File "/usr/local/lib/python3.9/site-packages/sqlalchemy/orm/session.py", line 2540, in flush
    self._flush(objects)
  File "/usr/local/lib/python3.9/site-packages/sqlalchemy/orm/session.py", line 2682, in _flush
    transaction.rollback(_capture_exception=True)
  File "/usr/local/lib/python3.9/site-packages/sqlalchemy/util/langhelpers.py", line 68, in __exit__
    compat.raise_(
  File "/usr/local/lib/python3.9/site-packages/sqlalchemy/util/compat.py", line 182, in raise_
    raise exception
  File "/usr/local/lib/python3.9/site-packages/sqlalchemy/orm/session.py", line 2642, in _flush
    flush_context.execute()
  File "/usr/local/lib/python3.9/site-packages/sqlalchemy/orm/unitofwork.py", line 422, in execute
    rec.execute(self)
  File "/usr/local/lib/python3.9/site-packages/sqlalchemy/orm/unitofwork.py", line 586, in execute
    persistence.save_obj(
  File "/usr/local/lib/python3.9/site-packages/sqlalchemy/orm/persistence.py", line 239, in save_obj
    _emit_insert_statements(
  File "/usr/local/lib/python3.9/site-packages/sqlalchemy/orm/persistence.py", line 1083, in _emit_insert_statements
    c = cached_connections[connection].execute(statement, multiparams)
  File "/usr/local/lib/python3.9/site-packages/sqlalchemy/engine/base.py", line 1011, in execute
    return meth(self, multiparams, params)
  File "/usr/local/lib/python3.9/site-packages/sqlalchemy/sql/elements.py", line 298, in _execute_on_connection
    return connection._execute_clauseelement(self, multiparams, params)
  File "/usr/local/lib/python3.9/site-packages/sqlalchemy/engine/base.py", line 1124, in _execute_clauseelement
    ret = self._execute_context(
  File "/usr/local/lib/python3.9/site-packages/sqlalchemy/engine/base.py", line 1316, in _execute_context
    self._handle_dbapi_exception(
  File "/usr/local/lib/python3.9/site-packages/sqlalchemy/engine/base.py", line 1510, in _handle_dbapi_exception
    util.raise_(
  File "/usr/local/lib/python3.9/site-packages/sqlalchemy/util/compat.py", line 182, in raise_
    raise exception
  File "/usr/local/lib/python3.9/site-packages/sqlalchemy/engine/base.py", line 1276, in _execute_context
    self.dialect.do_execute(
  File "/usr/local/lib/python3.9/site-packages/sqlalchemy/engine/default.py", line 608, in do_execute
    cursor.execute(statement, parameters)
sqlalchemy.exc.IntegrityError: (sqlite3.IntegrityError) UNIQUE constraint failed: rendered_task_instance_fields.dag_id, rendered_task_instance_fields.task_id, rendered_task_instance_fields.execution_date
[SQL: INSERT INTO rendered_task_instance_fields (dag_id, task_id, execution_date, rendered_fields, k8s_pod_yaml) VALUES (?, ?, ?, ?, ?)]
[parameters: ('elt', 'cleaning', '2021-11-27 04:50:00.000000', '{"bash_command": "/Users/Home/Airflow/tasks/cleaning.py /Users/Home/Airflow/unzip /Users/Home/Airflow/output", "env": null}', 'null')]
(Background on this error at: http://sqlalche.me/e/13/gkpj)
[2021-11-27 11:51:07,178] {taskinstance.py:1270} INFO - Marking task as UP_FOR_RETRY. dag_id=elt, task_id=cleaning, execution_date=20211127T045000, start_date=20211127T045107, end_date=20211127T045107
[2021-11-27 11:51:07,186] {standard_task_runner.py:88} ERROR - Failed to execute job 602 for task cleaning
Traceback (most recent call last):
  File "/usr/local/lib/python3.9/site-packages/sqlalchemy/engine/base.py", line 1276, in _execute_context
    self.dialect.do_execute(
  File "/usr/local/lib/python3.9/site-packages/sqlalchemy/engine/default.py", line 608, in do_execute
    cursor.execute(statement, parameters)
sqlite3.IntegrityError: UNIQUE constraint failed: rendered_task_instance_fields.dag_id, rendered_task_instance_fields.task_id, rendered_task_instance_fields.execution_date

The above exception was the direct cause of the following exception:

Traceback (most recent call last):
  File "/usr/local/lib/python3.9/site-packages/airflow/task/task_runner/standard_task_runner.py", line 85, in _start_by_fork
    args.func(args, dag=self.dag)
  File "/usr/local/lib/python3.9/site-packages/airflow/cli/cli_parser.py", line 48, in command
    return func(*args, **kwargs)
  File "/usr/local/lib/python3.9/site-packages/airflow/utils/cli.py", line 92, in wrapper
    return f(*args, **kwargs)
  File "/usr/local/lib/python3.9/site-packages/airflow/cli/commands/task_command.py", line 292, in task_run
    _run_task_by_selected_method(args, dag, ti)
  File "/usr/local/lib/python3.9/site-packages/airflow/cli/commands/task_command.py", line 107, in _run_task_by_selected_method
    _run_raw_task(args, ti)
  File "/usr/local/lib/python3.9/site-packages/airflow/cli/commands/task_command.py", line 180, in _run_raw_task
    ti._run_raw_task(
  File "/usr/local/lib/python3.9/site-packages/airflow/utils/session.py", line 70, in wrapper
    return func(*args, session=session, **kwargs)
  File "/usr/local/lib/python3.9/site-packages/airflow/models/taskinstance.py", line 1332, in _run_raw_task
    self._execute_task_with_callbacks(context)
  File "/usr/local/lib/python3.9/site-packages/airflow/models/taskinstance.py", line 1422, in _execute_task_with_callbacks
    RenderedTaskInstanceFields.write(RenderedTaskInstanceFields(ti=self, render_templates=False))
  File "/usr/local/lib/python3.9/site-packages/airflow/utils/session.py", line 70, in wrapper
    return func(*args, session=session, **kwargs)
  File "/usr/local/Cellar/python@3.9/3.9.9/Frameworks/Python.framework/Versions/3.9/lib/python3.9/contextlib.py", line 126, in __exit__
    next(self.gen)
  File "/usr/local/lib/python3.9/site-packages/airflow/utils/session.py", line 32, in create_session
    session.commit()
  File "/usr/local/lib/python3.9/site-packages/sqlalchemy/orm/session.py", line 1046, in commit
    self.transaction.commit()
  File "/usr/local/lib/python3.9/site-packages/sqlalchemy/orm/session.py", line 504, in commit
    self._prepare_impl()
  File "/usr/local/lib/python3.9/site-packages/sqlalchemy/orm/session.py", line 483, in _prepare_impl
    self.session.flush()
  File "/usr/local/lib/python3.9/site-packages/sqlalchemy/orm/session.py", line 2540, in flush
    self._flush(objects)
  File "/usr/local/lib/python3.9/site-packages/sqlalchemy/orm/session.py", line 2682, in _flush
    transaction.rollback(_capture_exception=True)
  File "/usr/local/lib/python3.9/site-packages/sqlalchemy/util/langhelpers.py", line 68, in __exit__
    compat.raise_(
  File "/usr/local/lib/python3.9/site-packages/sqlalchemy/util/compat.py", line 182, in raise_
    raise exception
  File "/usr/local/lib/python3.9/site-packages/sqlalchemy/orm/session.py", line 2642, in _flush
    flush_context.execute()
  File "/usr/local/lib/python3.9/site-packages/sqlalchemy/orm/unitofwork.py", line 422, in execute
    rec.execute(self)
  File "/usr/local/lib/python3.9/site-packages/sqlalchemy/orm/unitofwork.py", line 586, in execute
    persistence.save_obj(
  File "/usr/local/lib/python3.9/site-packages/sqlalchemy/orm/persistence.py", line 239, in save_obj
    _emit_insert_statements(
  File "/usr/local/lib/python3.9/site-packages/sqlalchemy/orm/persistence.py", line 1083, in _emit_insert_statements
    c = cached_connections[connection].execute(statement, multiparams)
  File "/usr/local/lib/python3.9/site-packages/sqlalchemy/engine/base.py", line 1011, in execute
    return meth(self, multiparams, params)
  File "/usr/local/lib/python3.9/site-packages/sqlalchemy/sql/elements.py", line 298, in _execute_on_connection
    return connection._execute_clauseelement(self, multiparams, params)
  File "/usr/local/lib/python3.9/site-packages/sqlalchemy/engine/base.py", line 1124, in _execute_clauseelement
    ret = self._execute_context(
  File "/usr/local/lib/python3.9/site-packages/sqlalchemy/engine/base.py", line 1316, in _execute_context
    self._handle_dbapi_exception(
  File "/usr/local/lib/python3.9/site-packages/sqlalchemy/engine/base.py", line 1510, in _handle_dbapi_exception
    util.raise_(
  File "/usr/local/lib/python3.9/site-packages/sqlalchemy/util/compat.py", line 182, in raise_
    raise exception
  File "/usr/local/lib/python3.9/site-packages/sqlalchemy/engine/base.py", line 1276, in _execute_context
    self.dialect.do_execute(
  File "/usr/local/lib/python3.9/site-packages/sqlalchemy/engine/default.py", line 608, in do_execute
    cursor.execute(statement, parameters)
sqlalchemy.exc.IntegrityError: (sqlite3.IntegrityError) UNIQUE constraint failed: rendered_task_instance_fields.dag_id, rendered_task_instance_fields.task_id, rendered_task_instance_fields.execution_date
[SQL: INSERT INTO rendered_task_instance_fields (dag_id, task_id, execution_date, rendered_fields, k8s_pod_yaml) VALUES (?, ?, ?, ?, ?)]
[parameters: ('elt', 'cleaning', '2021-11-27 04:50:00.000000', '{"bash_command": "/Users/Home/Airflow/tasks/cleaning.py /Users/Home/Airflow/unzip /Users/Home/Airflow/output", "env": null}', 'null')]
(Background on this error at: http://sqlalche.me/e/13/gkpj)
[2021-11-27 11:51:07,206] {local_task_job.py:154} INFO - Task exited with return code 1
[2021-11-27 11:51:07,218] {subprocess.py:93} INFO - Command exited with return code 0
[2021-11-27 11:51:07,226] {local_task_job.py:264} INFO - 0 downstream tasks scheduled from follow-on schedule check
[2021-11-27 11:51:07,232] {taskinstance.py:1270} INFO - Marking task as SUCCESS. dag_id=elt, task_id=cleaning, execution_date=20211127T045000, start_date=20211127T045107, end_date=20211127T045107
[2021-11-27 11:51:07,277] {local_task_job.py:154} INFO - Task exited with return code 0
[2021-11-27 11:51:07,297] {local_task_job.py:264} INFO - 1 downstream tasks scheduled from follow-on schedule check
