[2021-11-27 06:13:23,901] {taskinstance.py:1035} INFO - Dependencies all met for <TaskInstance: elt.cleaning scheduled__2021-11-26T23:07:00+00:00 [queued]>
[2021-11-27 06:13:23,906] {taskinstance.py:1035} INFO - Dependencies all met for <TaskInstance: elt.cleaning scheduled__2021-11-26T23:07:00+00:00 [queued]>
[2021-11-27 06:13:23,906] {taskinstance.py:1241} INFO - 
--------------------------------------------------------------------------------
[2021-11-27 06:13:23,906] {taskinstance.py:1242} INFO - Starting attempt 1 of 2
[2021-11-27 06:13:23,906] {taskinstance.py:1243} INFO - 
--------------------------------------------------------------------------------
[2021-11-27 06:13:23,917] {taskinstance.py:1262} INFO - Executing <Task(BashOperator): cleaning> on 2021-11-26 23:07:00+00:00
[2021-11-27 06:13:23,920] {standard_task_runner.py:52} INFO - Started process 1876 to run task
[2021-11-27 06:13:23,925] {standard_task_runner.py:76} INFO - Running: ['airflow', 'tasks', 'run', 'elt', 'cleaning', 'scheduled__2021-11-26T23:07:00+00:00', '--job-id', '19', '--raw', '--subdir', 'DAGS_FOLDER/processing.py', '--cfg-path', '/var/folders/hj/g8v71bv11_gb814qbbwch8zc0000gn/T/tmpdx82kzaj', '--error-file', '/var/folders/hj/g8v71bv11_gb814qbbwch8zc0000gn/T/tmpbw644zai']
[2021-11-27 06:13:23,926] {standard_task_runner.py:77} INFO - Job 19: Subtask cleaning
[2021-11-27 06:13:23,954] {logging_mixin.py:109} INFO - Running <TaskInstance: elt.cleaning scheduled__2021-11-26T23:07:00+00:00 [running]> on host 1.0.0.0.0.0.0.0.0.0.0.0.0.0.0.0.0.0.0.0.0.0.0.0.0.0.0.0.0.0.0.0.ip6.arpa
[2021-11-27 06:13:23,980] {taskinstance.py:1427} INFO - Exporting the following env vars:
AIRFLOW_CTX_DAG_EMAIL=airflow@example.com
AIRFLOW_CTX_DAG_OWNER=airflow
AIRFLOW_CTX_DAG_ID=elt
AIRFLOW_CTX_TASK_ID=cleaning
AIRFLOW_CTX_EXECUTION_DATE=2021-11-26T23:07:00+00:00
AIRFLOW_CTX_DAG_RUN_ID=scheduled__2021-11-26T23:07:00+00:00
[2021-11-27 06:13:23,980] {subprocess.py:62} INFO - Tmp dir root location: 
 /var/folders/hj/g8v71bv11_gb814qbbwch8zc0000gn/T
[2021-11-27 06:13:23,981] {subprocess.py:74} INFO - Running command: ['bash', '-c', '/Users/Home/Airflow/tasks/cleaning.py /Users/Home/Airflow/unzip /Users/Home/Airflow/output']
[2021-11-27 06:13:23,986] {subprocess.py:85} INFO - Output:
[2021-11-27 06:13:24,031] {subprocess.py:89} INFO - API_SH.STA.MMRT_DS2_en_csv_v2_3159367.csv
[2021-11-27 06:13:24,032] {subprocess.py:89} INFO - Traceback (most recent call last):
[2021-11-27 06:13:24,032] {subprocess.py:89} INFO -   File "/usr/local/Cellar/python@3.9/3.9.9/Frameworks/Python.framework/Versions/3.9/lib/python3.9/shutil.py", line 815, in move
[2021-11-27 06:13:24,033] {subprocess.py:89} INFO -     os.rename(src, real_dst)
[2021-11-27 06:13:24,033] {subprocess.py:89} INFO - FileNotFoundError: [Errno 2] No such file or directory: '/Users/Home/Airflow/unzip/API_SH.STA.MMRT_DS2_en_csv_v2_3159367.csv' -> '/Users/Home/Airflow/output/API_SH.STA.MMRT_DS2_en_csv_v2_3159367.csv'
[2021-11-27 06:13:24,033] {subprocess.py:89} INFO - 
[2021-11-27 06:13:24,033] {subprocess.py:89} INFO - During handling of the above exception, another exception occurred:
[2021-11-27 06:13:24,034] {subprocess.py:89} INFO - 
[2021-11-27 06:13:24,034] {subprocess.py:89} INFO - Traceback (most recent call last):
[2021-11-27 06:13:24,034] {subprocess.py:89} INFO -   File "/Users/Home/Airflow/tasks/cleaning.py", line 27, in <module>
[2021-11-27 06:13:24,034] {subprocess.py:89} INFO -     main()
[2021-11-27 06:13:24,034] {subprocess.py:89} INFO -   File "/Users/Home/Airflow/tasks/cleaning.py", line 22, in main
[2021-11-27 06:13:24,035] {subprocess.py:89} INFO -     shutil.move(path, os.path.join(args.output_folder,filename))
[2021-11-27 06:13:24,035] {subprocess.py:89} INFO -   File "/usr/local/Cellar/python@3.9/3.9.9/Frameworks/Python.framework/Versions/3.9/lib/python3.9/shutil.py", line 835, in move
[2021-11-27 06:13:24,035] {subprocess.py:89} INFO -     copy_function(src, real_dst)
[2021-11-27 06:13:24,035] {subprocess.py:89} INFO -   File "/usr/local/Cellar/python@3.9/3.9.9/Frameworks/Python.framework/Versions/3.9/lib/python3.9/shutil.py", line 444, in copy2
[2021-11-27 06:13:24,035] {subprocess.py:89} INFO -     copyfile(src, dst, follow_symlinks=follow_symlinks)
[2021-11-27 06:13:24,036] {subprocess.py:89} INFO -   File "/usr/local/Cellar/python@3.9/3.9.9/Frameworks/Python.framework/Versions/3.9/lib/python3.9/shutil.py", line 264, in copyfile
[2021-11-27 06:13:24,036] {subprocess.py:89} INFO -     with open(src, 'rb') as fsrc:
[2021-11-27 06:13:24,036] {subprocess.py:89} INFO - FileNotFoundError: [Errno 2] No such file or directory: '/Users/Home/Airflow/unzip/API_SH.STA.MMRT_DS2_en_csv_v2_3159367.csv'
[2021-11-27 06:13:24,038] {subprocess.py:93} INFO - Command exited with return code 1
[2021-11-27 06:13:24,046] {taskinstance.py:1703} ERROR - Task failed with exception
Traceback (most recent call last):
  File "/usr/local/lib/python3.9/site-packages/airflow/models/taskinstance.py", line 1332, in _run_raw_task
    self._execute_task_with_callbacks(context)
  File "/usr/local/lib/python3.9/site-packages/airflow/models/taskinstance.py", line 1458, in _execute_task_with_callbacks
    result = self._execute_task(context, self.task)
  File "/usr/local/lib/python3.9/site-packages/airflow/models/taskinstance.py", line 1514, in _execute_task
    result = execute_callable(context=context)
  File "/usr/local/lib/python3.9/site-packages/airflow/operators/bash.py", line 187, in execute
    raise AirflowException(
airflow.exceptions.AirflowException: Bash command failed. The command returned a non-zero exit code 1.
[2021-11-27 06:13:24,051] {taskinstance.py:1270} INFO - Marking task as UP_FOR_RETRY. dag_id=elt, task_id=cleaning, execution_date=20211126T230700, start_date=20211126T231323, end_date=20211126T231324
[2021-11-27 06:13:24,060] {standard_task_runner.py:88} ERROR - Failed to execute job 19 for task cleaning
Traceback (most recent call last):
  File "/usr/local/lib/python3.9/site-packages/airflow/task/task_runner/standard_task_runner.py", line 85, in _start_by_fork
    args.func(args, dag=self.dag)
  File "/usr/local/lib/python3.9/site-packages/airflow/cli/cli_parser.py", line 48, in command
    return func(*args, **kwargs)
  File "/usr/local/lib/python3.9/site-packages/airflow/utils/cli.py", line 92, in wrapper
    return f(*args, **kwargs)
  File "/usr/local/lib/python3.9/site-packages/airflow/cli/commands/task_command.py", line 292, in task_run
    _run_task_by_selected_method(args, dag, ti)
  File "/usr/local/lib/python3.9/site-packages/airflow/cli/commands/task_command.py", line 107, in _run_task_by_selected_method
    _run_raw_task(args, ti)
  File "/usr/local/lib/python3.9/site-packages/airflow/cli/commands/task_command.py", line 180, in _run_raw_task
    ti._run_raw_task(
  File "/usr/local/lib/python3.9/site-packages/airflow/utils/session.py", line 70, in wrapper
    return func(*args, session=session, **kwargs)
  File "/usr/local/lib/python3.9/site-packages/airflow/models/taskinstance.py", line 1332, in _run_raw_task
    self._execute_task_with_callbacks(context)
  File "/usr/local/lib/python3.9/site-packages/airflow/models/taskinstance.py", line 1458, in _execute_task_with_callbacks
    result = self._execute_task(context, self.task)
  File "/usr/local/lib/python3.9/site-packages/airflow/models/taskinstance.py", line 1514, in _execute_task
    result = execute_callable(context=context)
  File "/usr/local/lib/python3.9/site-packages/airflow/operators/bash.py", line 187, in execute
    raise AirflowException(
airflow.exceptions.AirflowException: Bash command failed. The command returned a non-zero exit code 1.
[2021-11-27 06:13:24,068] {local_task_job.py:154} INFO - Task exited with return code 1
[2021-11-27 06:13:24,088] {local_task_job.py:264} INFO - 0 downstream tasks scheduled from follow-on schedule check
